<mujoco model="humanoid">
  <compiler coordinate="local"/>
  <statistic extent="2" center="0 0 1"/>
  <option timestep="0.00555"/>
  <default>
    <motor ctrlrange="-1 1" ctrllimited="true"/>
    <geom type="capsule" condim="1" friction="1.0 0.05 0.05" solimp=".9 .99 .003" solref=".015 1"/>
    <joint type="hinge" damping="0.1" stiffness="5" armature=".007" limited="true" solimplimit="0 .99 .01"/>
    <site size=".04" group="3"/>
    <default class="force-torque">
      <site type="box" size=".01 .01 .02" rgba="1 0 0 1"/>
    </default>
    <default class="touch">
      <site type="capsule" rgba="0 0 1 .3"/>
    </default>
  </default>
  <asset>
    <texture type="skybox" builtin="gradient" rgb1=".4 .5 .6" rgb2="0 0 0" width="100" height="100"/>
    <texture builtin="flat" height="1278" mark="cross" markrgb="1 1 1" name="texgeom" random="0.01" rgb1="0.8 0.6 0.4" rgb2="0.8 0.6 0.4" type="cube" width="127"/>
    <texture builtin="checker" height="100" name="texplane" rgb1="0 0 0" rgb2="0.8 0.8 0.8" type="2d" width="100"/>
    <material name="MatPlane" reflectance="0.5" shininess="1" specular="1" texrepeat="60 60" texture="texplane"/>
    <material name="geom" texture="texgeom" texuniform="true"/>
    <mesh file="292791fd-6b61-41c4-8939-d2f5978dad9d/geom/Pelvis.stl" name="Pelvis_mesh"/>
    <mesh file="292791fd-6b61-41c4-8939-d2f5978dad9d/geom/L_Hip.stl" name="L_Hip_mesh"/>
    <mesh file="292791fd-6b61-41c4-8939-d2f5978dad9d/geom/R_Hip.stl" name="R_Hip_mesh"/>
    <mesh file="292791fd-6b61-41c4-8939-d2f5978dad9d/geom/Torso.stl" name="Torso_mesh"/>
    <mesh file="292791fd-6b61-41c4-8939-d2f5978dad9d/geom/L_Knee.stl" name="L_Knee_mesh"/>
    <mesh file="292791fd-6b61-41c4-8939-d2f5978dad9d/geom/R_Knee.stl" name="R_Knee_mesh"/>
    <mesh file="292791fd-6b61-41c4-8939-d2f5978dad9d/geom/Spine.stl" name="Spine_mesh"/>
    <mesh file="292791fd-6b61-41c4-8939-d2f5978dad9d/geom/L_Ankle.stl" name="L_Ankle_mesh"/>
    <mesh file="292791fd-6b61-41c4-8939-d2f5978dad9d/geom/R_Ankle.stl" name="R_Ankle_mesh"/>
    <mesh file="292791fd-6b61-41c4-8939-d2f5978dad9d/geom/Chest.stl" name="Chest_mesh"/>
    <mesh file="292791fd-6b61-41c4-8939-d2f5978dad9d/geom/L_Toe.stl" name="L_Toe_mesh"/>
    <mesh file="292791fd-6b61-41c4-8939-d2f5978dad9d/geom/R_Toe.stl" name="R_Toe_mesh"/>
    <mesh file="292791fd-6b61-41c4-8939-d2f5978dad9d/geom/Neck.stl" name="Neck_mesh"/>
    <mesh file="292791fd-6b61-41c4-8939-d2f5978dad9d/geom/L_Thorax.stl" name="L_Thorax_mesh"/>
    <mesh file="292791fd-6b61-41c4-8939-d2f5978dad9d/geom/R_Thorax.stl" name="R_Thorax_mesh"/>
    <mesh file="292791fd-6b61-41c4-8939-d2f5978dad9d/geom/Head.stl" name="Head_mesh"/>
    <mesh file="292791fd-6b61-41c4-8939-d2f5978dad9d/geom/L_Shoulder.stl" name="L_Shoulder_mesh"/>
    <mesh file="292791fd-6b61-41c4-8939-d2f5978dad9d/geom/R_Shoulder.stl" name="R_Shoulder_mesh"/>
    <mesh file="292791fd-6b61-41c4-8939-d2f5978dad9d/geom/L_Elbow.stl" name="L_Elbow_mesh"/>
    <mesh file="292791fd-6b61-41c4-8939-d2f5978dad9d/geom/R_Elbow.stl" name="R_Elbow_mesh"/>
    <mesh file="292791fd-6b61-41c4-8939-d2f5978dad9d/geom/L_Wrist.stl" name="L_Wrist_mesh"/>
    <mesh file="292791fd-6b61-41c4-8939-d2f5978dad9d/geom/R_Wrist.stl" name="R_Wrist_mesh"/>
    <mesh file="292791fd-6b61-41c4-8939-d2f5978dad9d/geom/L_Hand.stl" name="L_Hand_mesh"/>
    <mesh file="292791fd-6b61-41c4-8939-d2f5978dad9d/geom/R_Hand.stl" name="R_Hand_mesh"/>
  </asset>
  <worldbody>
    <light cutoff="100" diffuse="1 1 1" dir="-0 0 -1.3" directional="true" exponent="1" pos="0 0 1.3" specular=".1 .1 .1"/>
    <geom conaffinity="1" condim="3" name="floor" pos="0 0 0" rgba="0.8 0.9 0.8 1" size="100 100 .2" type="plane" material="MatPlane"/>
    <body name="Pelvis" pos="-0.0021 -0.2344 0.0368" quat="1.0000 0.0000 0.0000 0.0000">
      <freejoint name="Pelvis"/>
      <geom type="mesh" mesh="Pelvis_mesh" density="500" contype="1" conaffinity="1"/>
      <body name="L_Hip" pos="-0.0025 0.0726 -0.0949" quat="1.0000 0.0000 0.0000 0.0000">
        <joint name="L_Hip_x" type="hinge" pos="0 0 0" axis="1 0 0" stiffness="500" damping="50" armature="0.02" range="-180.0000 180.0000"/>
        <joint name="L_Hip_y" type="hinge" pos="0 0 0" axis="0 1 0" stiffness="500" damping="50" armature="0.02" range="-180.0000 180.0000"/>
        <joint name="L_Hip_z" type="hinge" pos="0 0 0" axis="0 0 1" stiffness="500" damping="50" armature="0.02" range="-180.0000 180.0000"/>
        <geom type="mesh" mesh="L_Hip_mesh" density="500" contype="1" conaffinity="1"/>
        <body name="L_Knee" pos="-0.0065 0.0343 -0.3816" quat="1.0000 0.0000 0.0000 0.0000">
          <joint name="L_Knee_x" type="hinge" pos="0 0 0" axis="1 0 0" stiffness="500" damping="50" armature="0.02" range="-5.6250 5.6250"/>
          <joint name="L_Knee_y" type="hinge" pos="0 0 0" axis="0 1 0" stiffness="500" damping="50" armature="0.02" range="-180.0000 180.0000"/>
          <joint name="L_Knee_z" type="hinge" pos="0 0 0" axis="0 0 1" stiffness="500" damping="50" armature="0.02" range="-5.6250 5.6250"/>
          <geom type="mesh" mesh="L_Knee_mesh" density="500" contype="1" conaffinity="1"/>
          <body name="L_Ankle" pos="-0.0464 -0.0152 -0.4126" quat="1.0000 0.0000 0.0000 0.0000">
            <joint name="L_Ankle_x" type="hinge" pos="0 0 0" axis="1 0 0" stiffness="400" damping="40" armature="0.01" range="-45.0000 45.0000"/>
            <joint name="L_Ankle_y" type="hinge" pos="0 0 0" axis="0 1 0" stiffness="400" damping="40" armature="0.01" range="-90.0000 90.0000"/>
            <joint name="L_Ankle_z" type="hinge" pos="0 0 0" axis="0 0 1" stiffness="400" damping="40" armature="0.01" range="-45.0000 45.0000"/>
            <geom density="228.08715" type="box" pos="0.0249 0.0243 -0.0245" size="0.0887 0.051 0.0484" quat="1.0000 0.0000 0.0000 0.0000"/>
            <body name="L_Toe" pos="0.1244 0.0275 -0.0573" quat="1.0000 0.0000 0.0000 0.0000">
              <joint name="L_Toe_x" type="hinge" pos="0 0 0" axis="1 0 0" stiffness="200" damping="20" armature="0.02" range="-5.6250 5.6250"/>
              <joint name="L_Toe_y" type="hinge" pos="0 0 0" axis="0 1 0" stiffness="200" damping="20" armature="0.02" range="-90.0000 90.0000"/>
              <joint name="L_Toe_z" type="hinge" pos="0 0 0" axis="0 0 1" stiffness="200" damping="20" armature="0.02" range="-5.6250 5.6250"/>
              <geom density="212.529103" type="box" pos="0.0262 -0.0032 0.0055" size="0.0524 0.0502 0.0211" quat="1.0000 0.0000 0.0000 0.0000"/>
            </body>
          </body>
        </body>
      </body>
      <body name="R_Hip" pos="0 -0.0712 -0.0941" quat="1.0000 0.0000 0.0000 0.0000">
        <joint name="R_Hip_x" type="hinge" pos="0 0 0" axis="1 0 0" stiffness="500" damping="50" armature="0.02" range="-180.0000 180.0000"/>
        <joint name="R_Hip_y" type="hinge" pos="0 0 0" axis="0 1 0" stiffness="500" damping="50" armature="0.02" range="-180.0000 180.0000"/>
        <joint name="R_Hip_z" type="hinge" pos="0 0 0" axis="0 0 1" stiffness="500" damping="50" armature="0.02" range="-180.0000 180.0000"/>
        <geom type="mesh" mesh="R_Hip_mesh" density="500" contype="1" conaffinity="1"/>
        <body name="R_Knee" pos="-0.0116 -0.038 -0.3907" quat="1.0000 0.0000 0.0000 0.0000">
          <joint name="R_Knee_x" type="hinge" pos="0 0 0" axis="1 0 0" stiffness="500" damping="50" armature="0.02" range="-5.6250 5.6250"/>
          <joint name="R_Knee_y" type="hinge" pos="0 0 0" axis="0 1 0" stiffness="500" damping="50" armature="0.02" range="-180.0000 180.0000"/>
          <joint name="R_Knee_z" type="hinge" pos="0 0 0" axis="0 0 1" stiffness="500" damping="50" armature="0.02" range="-5.6250 5.6250"/>
          <geom type="mesh" mesh="R_Knee_mesh" density="500" contype="1" conaffinity="1"/>
          <body name="R_Ankle" pos="-0.0453 0.017 -0.4139" quat="1.0000 0.0000 0.0000 0.0000">
            <joint name="R_Ankle_x" type="hinge" pos="0 0 0" axis="1 0 0" stiffness="400" damping="40" armature="0.01" range="-45.0000 45.0000"/>
            <joint name="R_Ankle_y" type="hinge" pos="0 0 0" axis="0 1 0" stiffness="400" damping="40" armature="0.01" range="-90.0000 90.0000"/>
            <joint name="R_Ankle_z" type="hinge" pos="0 0 0" axis="0 0 1" stiffness="400" damping="40" armature="0.01" range="-45.0000 45.0000"/>
            <geom density="218.232181" type="box" pos="0.0258 -0.0247 -0.0180" size="0.0897 0.051 0.0506" quat="1.0000 0.0000 0.0000 0.0000"/>
            <body name="R_Toe" pos="0.1286 -0.0297 -0.0499" quat="1.0000 0.0000 0.0000 0.0000">
              <joint name="R_Toe_x" type="hinge" pos="0 0 0" axis="1 0 0" stiffness="200" damping="20" armature="0.02" range="-5.6250 5.6250"/>
              <joint name="R_Toe_y" type="hinge" pos="0 0 0" axis="0 1 0" stiffness="200" damping="20" armature="0.02" range="-90.0000 90.0000"/>
              <joint name="R_Toe_z" type="hinge" pos="0 0 0" axis="0 0 1" stiffness="200" damping="20" armature="0.02" range="-5.6250 5.6250"/>
              <geom density="216.157696" type="box" pos="0.0226 0.0050 0.0033" size="0.0515 0.0507 0.022" quat="1.0000 0.0000 0.0000 0.0000"/>
            </body>
          </body>
        </body>
      </body>
      <body name="Torso" pos="-0.0356 -0.0025 0.116" quat="1.0000 0.0000 0.0000 0.0000">
        <joint name="Torso_x" type="hinge" pos="0 0 0" axis="1 0 0" stiffness="1000" damping="100" armature="0.02" range="-180.0000 180.0000"/>
        <joint name="Torso_y" type="hinge" pos="0 0 0" axis="0 1 0" stiffness="1000" damping="100" armature="0.02" range="-180.0000 180.0000"/>
        <joint name="Torso_z" type="hinge" pos="0 0 0" axis="0 0 1" stiffness="1000" damping="100" armature="0.02" range="-180.0000 180.0000"/>
        <geom type="mesh" mesh="Torso_mesh" density="500" contype="1" conaffinity="1"/>
        <body name="Spine" pos="-0.0007 0.0063 0.1378" quat="1.0000 0.0000 0.0000 0.0000">
          <joint name="Spine_x" type="hinge" pos="0 0 0" axis="1 0 0" stiffness="1000" damping="100" armature="0.02" range="-180.0000 180.0000"/>
          <joint name="Spine_y" type="hinge" pos="0 0 0" axis="0 1 0" stiffness="1000" damping="100" armature="0.02" range="-180.0000 180.0000"/>
          <joint name="Spine_z" type="hinge" pos="0 0 0" axis="0 0 1" stiffness="1000" damping="100" armature="0.02" range="-180.0000 180.0000"/>
          <geom type="mesh" mesh="Spine_mesh" density="500" contype="1" conaffinity="1"/>
          <body name="Chest" pos="0.0269 0.0012 0.0556" quat="1.0000 0.0000 0.0000 0.0000">
            <joint name="Chest_x" type="hinge" pos="0 0 0" axis="1 0 0" stiffness="1000" damping="100" armature="0.02" range="-180.0000 180.0000"/>
            <joint name="Chest_y" type="hinge" pos="0 0 0" axis="0 1 0" stiffness="1000" damping="100" armature="0.02" range="-180.0000 180.0000"/>
            <joint name="Chest_z" type="hinge" pos="0 0 0" axis="0 0 1" stiffness="1000" damping="100" armature="0.02" range="-180.0000 180.0000"/>
            <geom type="mesh" mesh="Chest_mesh" density="500" contype="1" conaffinity="1"/>
            <body name="Neck" pos="-0.0449 -0.0028 0.2232" quat="1.0000 0.0000 0.0000 0.0000">
              <joint name="Neck_x" type="hinge" pos="0 0 0" axis="1 0 0" stiffness="100" damping="10" armature="0.02" range="-180.0000 180.0000"/>
              <joint name="Neck_y" type="hinge" pos="0 0 0" axis="0 1 0" stiffness="100" damping="10" armature="0.02" range="-180.0000 180.0000"/>
              <joint name="Neck_z" type="hinge" pos="0 0 0" axis="0 0 1" stiffness="100" damping="10" armature="0.02" range="-180.0000 180.0000"/>
              <geom type="mesh" mesh="Neck_mesh" density="500" contype="1" conaffinity="1"/>
              <body name="Head" pos="0.0515 0.0053 0.0635" quat="1.0000 0.0000 0.0000 0.0000">
                <joint name="Head_x" type="hinge" pos="0 0 0" axis="1 0 0" stiffness="100" damping="10" armature="0.02" range="-180.0000 180.0000"/>
                <joint name="Head_y" type="hinge" pos="0 0 0" axis="0 1 0" stiffness="100" damping="10" armature="0.02" range="-180.0000 180.0000"/>
                <joint name="Head_z" type="hinge" pos="0 0 0" axis="0 0 1" stiffness="100" damping="10" armature="0.02" range="-180.0000 180.0000"/>
                <geom type="mesh" mesh="Head_mesh" density="500" contype="1" conaffinity="1"/>
              </body>
            </body>
            <body name="L_Thorax" pos="-0.035 0.0856 0.1288" quat="1.0000 0.0000 0.0000 0.0000">
              <joint name="L_Thorax_x" type="hinge" pos="0 0 0" axis="1 0 0" stiffness="400" damping="40" armature="0.02" range="-180.0000 180.0000"/>
              <joint name="L_Thorax_y" type="hinge" pos="0 0 0" axis="0 1 0" stiffness="400" damping="40" armature="0.02" range="-180.0000 180.0000"/>
              <joint name="L_Thorax_z" type="hinge" pos="0 0 0" axis="0 0 1" stiffness="400" damping="40" armature="0.02" range="-180.0000 180.0000"/>
              <geom type="mesh" mesh="L_Thorax_mesh" density="500" contype="1" conaffinity="1"/>
              <body name="L_Shoulder" pos="-0.0115 0.0982 0.0303" quat="1.0000 0.0000 0.0000 0.0000">
                <joint name="L_Shoulder_x" type="hinge" pos="0 0 0" axis="1 0 0" stiffness="400" damping="40" armature="0.02" range="-720.0000 720.0000"/>
                <joint name="L_Shoulder_y" type="hinge" pos="0 0 0" axis="0 1 0" stiffness="400" damping="40" armature="0.02" range="-720.0000 720.0000"/>
                <joint name="L_Shoulder_z" type="hinge" pos="0 0 0" axis="0 0 1" stiffness="400" damping="40" armature="0.02" range="-720.0000 720.0000"/>
                <geom type="mesh" mesh="L_Shoulder_mesh" density="500" contype="1" conaffinity="1"/>
                <body name="L_Elbow" pos="-0.0299 0.2679 -0.0124" quat="1.0000 0.0000 0.0000 0.0000">
                  <joint name="L_Elbow_x" type="hinge" pos="0 0 0" axis="1 0 0" stiffness="300" damping="30" armature="0.02" range="-720.0000 720.0000"/>
                  <joint name="L_Elbow_y" type="hinge" pos="0 0 0" axis="0 1 0" stiffness="300" damping="30" armature="0.02" range="-720.0000 720.0000"/>
                  <joint name="L_Elbow_z" type="hinge" pos="0 0 0" axis="0 0 1" stiffness="300" damping="30" armature="0.02" range="-720.0000 720.0000"/>
                  <geom type="mesh" mesh="L_Elbow_mesh" density="500" contype="1" conaffinity="1"/>
                  <body name="L_Wrist" pos="-0.0007 0.2604 0.0096" quat="1.0000 0.0000 0.0000 0.0000">
                    <joint name="L_Wrist_x" type="hinge" pos="0 0 0" axis="1 0 0" stiffness="100" damping="10" armature="0.02" range="-180.0000 180.0000"/>
                    <joint name="L_Wrist_y" type="hinge" pos="0 0 0" axis="0 1 0" stiffness="100" damping="10" armature="0.02" range="-180.0000 180.0000"/>
                    <joint name="L_Wrist_z" type="hinge" pos="0 0 0" axis="0 0 1" stiffness="100" damping="10" armature="0.02" range="-180.0000 180.0000"/>
                    <geom type="mesh" mesh="L_Wrist_mesh" density="500" contype="1" conaffinity="1"/>
                    <body name="L_Hand" pos="-0.0163 0.0889 -0.0073" quat="1.0000 0.0000 0.0000 0.0000">
                      <joint name="L_Hand_x" type="hinge" pos="0 0 0" axis="1 0 0" stiffness="100" damping="10" armature="0.02" range="-180.0000 180.0000"/>
                      <joint name="L_Hand_y" type="hinge" pos="0 0 0" axis="0 1 0" stiffness="100" damping="10" armature="0.02" range="-180.0000 180.0000"/>
                      <joint name="L_Hand_z" type="hinge" pos="0 0 0" axis="0 0 1" stiffness="100" damping="10" armature="0.02" range="-180.0000 180.0000"/>
                      <geom type="mesh" mesh="L_Hand_mesh" density="500" contype="1" conaffinity="1"/>
                    </body>
                  </body>
                </body>
              </body>
            </body>
            <body name="R_Thorax" pos="-0.0394 -0.0889 0.1255" quat="1.0000 0.0000 0.0000 0.0000">
              <joint name="R_Thorax_x" type="hinge" pos="0 0 0" axis="1 0 0" stiffness="400" damping="40" armature="0.02" range="-180.0000 180.0000"/>
              <joint name="R_Thorax_y" type="hinge" pos="0 0 0" axis="0 1 0" stiffness="400" damping="40" armature="0.02" range="-180.0000 180.0000"/>
              <joint name="R_Thorax_z" type="hinge" pos="0 0 0" axis="0 0 1" stiffness="400" damping="40" armature="0.02" range="-180.0000 180.0000"/>
              <geom type="mesh" mesh="R_Thorax_mesh" density="500" contype="1" conaffinity="1"/>
              <body name="R_Shoulder" pos="-0.0103 -0.104 0.0328" quat="1.0000 0.0000 0.0000 0.0000">
                <joint name="R_Shoulder_x" type="hinge" pos="0 0 0" axis="1 0 0" stiffness="400" damping="40" armature="0.02" range="-720.0000 720.0000"/>
                <joint name="R_Shoulder_y" type="hinge" pos="0 0 0" axis="0 1 0" stiffness="400" damping="40" armature="0.02" range="-720.0000 720.0000"/>
                <joint name="R_Shoulder_z" type="hinge" pos="0 0 0" axis="0 0 1" stiffness="400" damping="40" armature="0.02" range="-720.0000 720.0000"/>
                <geom type="mesh" mesh="R_Shoulder_mesh" density="500" contype="1" conaffinity="1"/>
                <body name="R_Elbow" pos="-0.0245 -0.2628 -0.0123" quat="1.0000 0.0000 0.0000 0.0000">
                  <joint name="R_Elbow_x" type="hinge" pos="0 0 0" axis="1 0 0" stiffness="300" damping="30" armature="0.02" range="-720.0000 720.0000"/>
                  <joint name="R_Elbow_y" type="hinge" pos="0 0 0" axis="0 1 0" stiffness="300" damping="30" armature="0.02" range="-720.0000 720.0000"/>
                  <joint name="R_Elbow_z" type="hinge" pos="0 0 0" axis="0 0 1" stiffness="300" damping="30" armature="0.02" range="-720.0000 720.0000"/>
                  <geom type="mesh" mesh="R_Elbow_mesh" density="500" contype="1" conaffinity="1"/>
                  <body name="R_Wrist" pos="-0.0058 -0.2649 0.0078" quat="1.0000 0.0000 0.0000 0.0000">
                    <joint name="R_Wrist_x" type="hinge" pos="0 0 0" axis="1 0 0" stiffness="100" damping="10" armature="0.02" range="-180.0000 180.0000"/>
                    <joint name="R_Wrist_y" type="hinge" pos="0 0 0" axis="0 1 0" stiffness="100" damping="10" armature="0.02" range="-180.0000 180.0000"/>
                    <joint name="R_Wrist_z" type="hinge" pos="0 0 0" axis="0 0 1" stiffness="100" damping="10" armature="0.02" range="-180.0000 180.0000"/>
                    <geom type="mesh" mesh="R_Wrist_mesh" density="500" contype="1" conaffinity="1"/>
                    <body name="R_Hand" pos="-0.0106 -0.0895 -0.0056" quat="1.0000 0.0000 0.0000 0.0000">
                      <joint name="R_Hand_x" type="hinge" pos="0 0 0" axis="1 0 0" stiffness="100" damping="10" armature="0.02" range="-180.0000 180.0000"/>
                      <joint name="R_Hand_y" type="hinge" pos="0 0 0" axis="0 1 0" stiffness="100" damping="10" armature="0.02" range="-180.0000 180.0000"/>
                      <joint name="R_Hand_z" type="hinge" pos="0 0 0" axis="0 0 1" stiffness="100" damping="10" armature="0.02" range="-180.0000 180.0000"/>
                      <geom type="mesh" mesh="R_Hand_mesh" density="500" contype="1" conaffinity="1"/>
                    </body>
                  </body>
                </body>
              </body>
            </body>
          </body>
        </body>
      </body>
    </body>
  </worldbody>
  <actuator>
    <motor name="L_Hip_x" joint="L_Hip_x" gear="1"/>
    <motor name="L_Hip_y" joint="L_Hip_y" gear="1"/>
    <motor name="L_Hip_z" joint="L_Hip_z" gear="1"/>
    <motor name="L_Knee_x" joint="L_Knee_x" gear="1"/>
    <motor name="L_Knee_y" joint="L_Knee_y" gear="1"/>
    <motor name="L_Knee_z" joint="L_Knee_z" gear="1"/>
    <motor name="L_Ankle_x" joint="L_Ankle_x" gear="1"/>
    <motor name="L_Ankle_y" joint="L_Ankle_y" gear="1"/>
    <motor name="L_Ankle_z" joint="L_Ankle_z" gear="1"/>
    <motor name="L_Toe_x" joint="L_Toe_x" gear="1"/>
    <motor name="L_Toe_y" joint="L_Toe_y" gear="1"/>
    <motor name="L_Toe_z" joint="L_Toe_z" gear="1"/>
    <motor name="R_Hip_x" joint="R_Hip_x" gear="1"/>
    <motor name="R_Hip_y" joint="R_Hip_y" gear="1"/>
    <motor name="R_Hip_z" joint="R_Hip_z" gear="1"/>
    <motor name="R_Knee_x" joint="R_Knee_x" gear="1"/>
    <motor name="R_Knee_y" joint="R_Knee_y" gear="1"/>
    <motor name="R_Knee_z" joint="R_Knee_z" gear="1"/>
    <motor name="R_Ankle_x" joint="R_Ankle_x" gear="1"/>
    <motor name="R_Ankle_y" joint="R_Ankle_y" gear="1"/>
    <motor name="R_Ankle_z" joint="R_Ankle_z" gear="1"/>
    <motor name="R_Toe_x" joint="R_Toe_x" gear="1"/>
    <motor name="R_Toe_y" joint="R_Toe_y" gear="1"/>
    <motor name="R_Toe_z" joint="R_Toe_z" gear="1"/>
    <motor name="Torso_x" joint="Torso_x" gear="1"/>
    <motor name="Torso_y" joint="Torso_y" gear="1"/>
    <motor name="Torso_z" joint="Torso_z" gear="1"/>
    <motor name="Spine_x" joint="Spine_x" gear="1"/>
    <motor name="Spine_y" joint="Spine_y" gear="1"/>
    <motor name="Spine_z" joint="Spine_z" gear="1"/>
    <motor name="Chest_x" joint="Chest_x" gear="1"/>
    <motor name="Chest_y" joint="Chest_y" gear="1"/>
    <motor name="Chest_z" joint="Chest_z" gear="1"/>
    <motor name="Neck_x" joint="Neck_x" gear="1"/>
    <motor name="Neck_y" joint="Neck_y" gear="1"/>
    <motor name="Neck_z" joint="Neck_z" gear="1"/>
    <motor name="Head_x" joint="Head_x" gear="1"/>
    <motor name="Head_y" joint="Head_y" gear="1"/>
    <motor name="Head_z" joint="Head_z" gear="1"/>
    <motor name="L_Thorax_x" joint="L_Thorax_x" gear="1"/>
    <motor name="L_Thorax_y" joint="L_Thorax_y" gear="1"/>
    <motor name="L_Thorax_z" joint="L_Thorax_z" gear="1"/>
    <motor name="L_Shoulder_x" joint="L_Shoulder_x" gear="1"/>
    <motor name="L_Shoulder_y" joint="L_Shoulder_y" gear="1"/>
    <motor name="L_Shoulder_z" joint="L_Shoulder_z" gear="1"/>
    <motor name="L_Elbow_x" joint="L_Elbow_x" gear="1"/>
    <motor name="L_Elbow_y" joint="L_Elbow_y" gear="1"/>
    <motor name="L_Elbow_z" joint="L_Elbow_z" gear="1"/>
    <motor name="L_Wrist_x" joint="L_Wrist_x" gear="1"/>
    <motor name="L_Wrist_y" joint="L_Wrist_y" gear="1"/>
    <motor name="L_Wrist_z" joint="L_Wrist_z" gear="1"/>
    <motor name="L_Hand_x" joint="L_Hand_x" gear="1"/>
    <motor name="L_Hand_y" joint="L_Hand_y" gear="1"/>
    <motor name="L_Hand_z" joint="L_Hand_z" gear="1"/>
    <motor name="R_Thorax_x" joint="R_Thorax_x" gear="1"/>
    <motor name="R_Thorax_y" joint="R_Thorax_y" gear="1"/>
    <motor name="R_Thorax_z" joint="R_Thorax_z" gear="1"/>
    <motor name="R_Shoulder_x" joint="R_Shoulder_x" gear="1"/>
    <motor name="R_Shoulder_y" joint="R_Shoulder_y" gear="1"/>
    <motor name="R_Shoulder_z" joint="R_Shoulder_z" gear="1"/>
    <motor name="R_Elbow_x" joint="R_Elbow_x" gear="1"/>
    <motor name="R_Elbow_y" joint="R_Elbow_y" gear="1"/>
    <motor name="R_Elbow_z" joint="R_Elbow_z" gear="1"/>
    <motor name="R_Wrist_x" joint="R_Wrist_x" gear="1"/>
    <motor name="R_Wrist_y" joint="R_Wrist_y" gear="1"/>
    <motor name="R_Wrist_z" joint="R_Wrist_z" gear="1"/>
    <motor name="R_Hand_x" joint="R_Hand_x" gear="1"/>
    <motor name="R_Hand_y" joint="R_Hand_y" gear="1"/>
    <motor name="R_Hand_z" joint="R_Hand_z" gear="1"/>
  </actuator>
  <contact>
    <exclude body1="Chest" body2="L_Shoulder"/>
    <exclude body1="Chest" body2="R_Shoulder"/>
    <exclude body1="Chest" body2="R_Thorax"/>
    <exclude body1="Chest" body2="L_Thorax"/>
    <exclude body1="L_Hip" body2="Pelvis"/>
    <exclude body1="R_Hip" body2="Pelvis"/>
    <exclude body1="Torso" body2="Pelvis"/>
    <exclude body1="L_Knee" body2="L_Hip"/>
    <exclude body1="R_Knee" body2="R_Hip"/>
    <exclude body1="Spine" body2="Torso"/>
    <exclude body1="L_Ankle" body2="L_Knee"/>
    <exclude body1="R_Ankle" body2="R_Knee"/>
    <exclude body1="Chest" body2="Spine"/>
    <exclude body1="L_Toe" body2="L_Ankle"/>
    <exclude body1="R_Toe" body2="R_Ankle"/>
    <exclude body1="Neck" body2="Chest"/>
    <exclude body1="L_Thorax" body2="Chest"/>
    <exclude body1="R_Thorax" body2="Chest"/>
    <exclude body1="Head" body2="Neck"/>
    <exclude body1="L_Shoulder" body2="L_Thorax"/>
    <exclude body1="R_Shoulder" body2="R_Thorax"/>
    <exclude body1="L_Elbow" body2="L_Shoulder"/>
    <exclude body1="R_Elbow" body2="R_Shoulder"/>
    <exclude body1="L_Wrist" body2="L_Elbow"/>
    <exclude body1="R_Wrist" body2="R_Elbow"/>
    <exclude body1="L_Hand" body2="L_Wrist"/>
    <exclude body1="R_Hand" body2="R_Wrist"/>
  </contact>
  <size njmax="2500" nconmax="500"/>
</mujoco>
